[2024-11-26T07:41:38.689+0000] {local_task_job_runner.py:123} INFO - ::group::Pre task execution logs
[2024-11-26T07:41:38.716+0000] {taskinstance.py:2612} INFO - Dependencies all met for dep_context=non-requeueable deps ti=<TaskInstance: extract_weather_dag.extract_data manual__2024-11-26T07:41:28.571022+00:00 map_index=1 [queued]>
[2024-11-26T07:41:38.728+0000] {taskinstance.py:2612} INFO - Dependencies all met for dep_context=requeueable deps ti=<TaskInstance: extract_weather_dag.extract_data manual__2024-11-26T07:41:28.571022+00:00 map_index=1 [queued]>
[2024-11-26T07:41:38.729+0000] {taskinstance.py:2865} INFO - Starting attempt 1 of 2
[2024-11-26T07:41:38.744+0000] {taskinstance.py:2888} INFO - Executing <Mapped(WeatherToCSVOperator): extract_data> on 2024-11-26 07:41:28.571022+00:00
[2024-11-26T07:41:38.751+0000] {standard_task_runner.py:104} INFO - Running: ['***', 'tasks', 'run', 'extract_weather_dag', 'extract_data', 'manual__2024-11-26T07:41:28.571022+00:00', '--job-id', '102', '--raw', '--subdir', 'DAGS_FOLDER/extract_weather.py', '--cfg-path', '/tmp/tmphblnvi4s', '--map-index', '1']
[2024-11-26T07:41:38.751+0000] {logging_mixin.py:190} WARNING - /home/***/.local/lib/python3.12/site-packages/***/task/task_runner/standard_task_runner.py:70 DeprecationWarning: This process (pid=839) is multi-threaded, use of fork() may lead to deadlocks in the child.
[2024-11-26T07:41:38.752+0000] {standard_task_runner.py:105} INFO - Job 102: Subtask extract_data
[2024-11-26T07:41:38.753+0000] {standard_task_runner.py:72} INFO - Started process 846 to run task
[2024-11-26T07:41:38.768+0000] {logging_mixin.py:190} WARNING - /home/***/.local/lib/python3.12/site-packages/***/settings.py:209 DeprecationWarning: The sql_alchemy_conn option in [core] has been moved to the sql_alchemy_conn option in [database] - the old setting has been used, but please update your config.
[2024-11-26T07:41:38.808+0000] {task_command.py:467} INFO - Running <TaskInstance: extract_weather_dag.extract_data manual__2024-11-26T07:41:28.571022+00:00 map_index=1 [running]> on host ac9b5e0c2e2c
[2024-11-26T07:41:38.900+0000] {taskinstance.py:3131} INFO - Exporting env vars: AIRFLOW_CTX_DAG_OWNER='***' AIRFLOW_CTX_DAG_ID='extract_weather_dag' AIRFLOW_CTX_TASK_ID='extract_data' AIRFLOW_CTX_EXECUTION_DATE='2024-11-26T07:41:28.571022+00:00' AIRFLOW_CTX_TRY_NUMBER='1' AIRFLOW_CTX_DAG_RUN_ID='manual__2024-11-26T07:41:28.571022+00:00'
[2024-11-26T07:41:38.902+0000] {taskinstance.py:731} INFO - ::endgroup::
[2024-11-26T07:41:38.905+0000] {operator.py:22} INFO - Fetching weather in Paris
[2024-11-26T07:41:38.919+0000] {base.py:84} INFO - Retrieving connection 'weather_api'
[2024-11-26T07:41:39.190+0000] {operator.py:25} INFO - Create DataFrame
[2024-11-26T07:41:39.192+0000] {operator.py:28} INFO - Writing weather to /opt/***/data/Paris_20241126.csv
[2024-11-26T07:41:39.193+0000] {taskinstance.py:3310} ERROR - Task failed with exception
Traceback (most recent call last):
  File "/home/airflow/.local/lib/python3.12/site-packages/airflow/models/taskinstance.py", line 767, in _execute_task
    result = _execute_callable(context=context, **execute_callable_kwargs)
             ^^^^^^^^^^^^^^^^^^^^^^^^^^^^^^^^^^^^^^^^^^^^^^^^^^^^^^^^^^^^^
  File "/home/airflow/.local/lib/python3.12/site-packages/airflow/models/taskinstance.py", line 733, in _execute_callable
    return ExecutionCallableRunner(
           ^^^^^^^^^^^^^^^^^^^^^^^^
  File "/home/airflow/.local/lib/python3.12/site-packages/airflow/utils/operator_helpers.py", line 252, in run
    return self.func(*args, **kwargs)
           ^^^^^^^^^^^^^^^^^^^^^^^^^^
  File "/home/airflow/.local/lib/python3.12/site-packages/airflow/models/baseoperator.py", line 406, in wrapper
    return func(self, *args, **kwargs)
           ^^^^^^^^^^^^^^^^^^^^^^^^^^^
  File "/opt/airflow/dags/custom/operator.py", line 29, in execute
    df.to_csv(self._file_path, index=False)
              ^^^^^^^^^^^^^^^
AttributeError: 'WeatherToCSVOperator' object has no attribute '_file_path'
[2024-11-26T07:41:39.215+0000] {taskinstance.py:1225} INFO - Marking task as UP_FOR_RETRY. dag_id=extract_weather_dag, task_id=extract_data, run_id=manual__2024-11-26T07:41:28.571022+00:00, map_index=1, execution_date=20241126T074128, start_date=20241126T074138, end_date=20241126T074139
[2024-11-26T07:41:39.231+0000] {taskinstance.py:340} INFO - ::group::Post task execution logs
[2024-11-26T07:41:39.232+0000] {standard_task_runner.py:124} ERROR - Failed to execute job 102 for task extract_data ('WeatherToCSVOperator' object has no attribute '_file_path'; 846)
Traceback (most recent call last):
  File "/home/airflow/.local/lib/python3.12/site-packages/airflow/task/task_runner/standard_task_runner.py", line 117, in _start_by_fork
    ret = args.func(args, dag=self.dag)
          ^^^^^^^^^^^^^^^^^^^^^^^^^^^^^
  File "/home/airflow/.local/lib/python3.12/site-packages/airflow/cli/cli_config.py", line 49, in command
    return func(*args, **kwargs)
           ^^^^^^^^^^^^^^^^^^^^^
  File "/home/airflow/.local/lib/python3.12/site-packages/airflow/utils/cli.py", line 115, in wrapper
    return f(*args, **kwargs)
           ^^^^^^^^^^^^^^^^^^
  File "/home/airflow/.local/lib/python3.12/site-packages/airflow/cli/commands/task_command.py", line 483, in task_run
    task_return_code = _run_task_by_selected_method(args, _dag, ti)
                       ^^^^^^^^^^^^^^^^^^^^^^^^^^^^^^^^^^^^^^^^^^^^
  File "/home/airflow/.local/lib/python3.12/site-packages/airflow/cli/commands/task_command.py", line 256, in _run_task_by_selected_method
    return _run_raw_task(args, ti)
           ^^^^^^^^^^^^^^^^^^^^^^^
  File "/home/airflow/.local/lib/python3.12/site-packages/airflow/cli/commands/task_command.py", line 341, in _run_raw_task
    return ti._run_raw_task(
           ^^^^^^^^^^^^^^^^^
  File "/home/airflow/.local/lib/python3.12/site-packages/airflow/utils/session.py", line 97, in wrapper
    return func(*args, session=session, **kwargs)
           ^^^^^^^^^^^^^^^^^^^^^^^^^^^^^^^^^^^^^^
  File "/home/airflow/.local/lib/python3.12/site-packages/airflow/models/taskinstance.py", line 3004, in _run_raw_task
    return _run_raw_task(
           ^^^^^^^^^^^^^^
  File "/home/airflow/.local/lib/python3.12/site-packages/airflow/models/taskinstance.py", line 273, in _run_raw_task
    TaskInstance._execute_task_with_callbacks(
  File "/home/airflow/.local/lib/python3.12/site-packages/airflow/models/taskinstance.py", line 3158, in _execute_task_with_callbacks
    result = self._execute_task(context, task_orig)
             ^^^^^^^^^^^^^^^^^^^^^^^^^^^^^^^^^^^^^^
  File "/home/airflow/.local/lib/python3.12/site-packages/airflow/models/taskinstance.py", line 3182, in _execute_task
    return _execute_task(self, context, task_orig)
           ^^^^^^^^^^^^^^^^^^^^^^^^^^^^^^^^^^^^^^^
  File "/home/airflow/.local/lib/python3.12/site-packages/airflow/models/taskinstance.py", line 767, in _execute_task
    result = _execute_callable(context=context, **execute_callable_kwargs)
             ^^^^^^^^^^^^^^^^^^^^^^^^^^^^^^^^^^^^^^^^^^^^^^^^^^^^^^^^^^^^^
  File "/home/airflow/.local/lib/python3.12/site-packages/airflow/models/taskinstance.py", line 733, in _execute_callable
    return ExecutionCallableRunner(
           ^^^^^^^^^^^^^^^^^^^^^^^^
  File "/home/airflow/.local/lib/python3.12/site-packages/airflow/utils/operator_helpers.py", line 252, in run
    return self.func(*args, **kwargs)
           ^^^^^^^^^^^^^^^^^^^^^^^^^^
  File "/home/airflow/.local/lib/python3.12/site-packages/airflow/models/baseoperator.py", line 406, in wrapper
    return func(self, *args, **kwargs)
           ^^^^^^^^^^^^^^^^^^^^^^^^^^^
  File "/opt/airflow/dags/custom/operator.py", line 29, in execute
    df.to_csv(self._file_path, index=False)
              ^^^^^^^^^^^^^^^
AttributeError: 'WeatherToCSVOperator' object has no attribute '_file_path'
[2024-11-26T07:41:39.250+0000] {local_task_job_runner.py:266} INFO - Task exited with return code 1
[2024-11-26T07:41:39.267+0000] {taskinstance.py:3900} INFO - 0 downstream tasks scheduled from follow-on schedule check
[2024-11-26T07:41:39.269+0000] {local_task_job_runner.py:245} INFO - ::endgroup::
