[2024-11-25T21:44:24.779+0000] {local_task_job_runner.py:123} INFO - ::group::Pre task execution logs
[2024-11-25T21:44:24.803+0000] {taskinstance.py:2612} INFO - Dependencies all met for dep_context=non-requeueable deps ti=<TaskInstance: extract_weather.extract_data manual__2024-11-25T21:43:37.102564+00:00 [queued]>
[2024-11-25T21:44:24.815+0000] {taskinstance.py:2612} INFO - Dependencies all met for dep_context=requeueable deps ti=<TaskInstance: extract_weather.extract_data manual__2024-11-25T21:43:37.102564+00:00 [queued]>
[2024-11-25T21:44:24.816+0000] {taskinstance.py:2865} INFO - Starting attempt 2 of 3
[2024-11-25T21:44:24.832+0000] {taskinstance.py:2888} INFO - Executing <Task(WeatherToCSVOperator): extract_data> on 2024-11-25 21:43:37.102564+00:00
[2024-11-25T21:44:24.837+0000] {standard_task_runner.py:72} INFO - Started process 120 to run task
[2024-11-25T21:44:24.839+0000] {standard_task_runner.py:104} INFO - Running: ['***', 'tasks', 'run', 'extract_weather', 'extract_data', 'manual__2024-11-25T21:43:37.102564+00:00', '--job-id', '5', '--raw', '--subdir', 'DAGS_FOLDER/extract_weather.py', '--cfg-path', '/tmp/tmpadl3moxr']
[2024-11-25T21:44:24.841+0000] {standard_task_runner.py:105} INFO - Job 5: Subtask extract_data
[2024-11-25T21:44:24.857+0000] {logging_mixin.py:190} WARNING - /home/***/.local/lib/python3.12/site-packages/***/settings.py:209 DeprecationWarning: The sql_alchemy_conn option in [core] has been moved to the sql_alchemy_conn option in [database] - the old setting has been used, but please update your config.
[2024-11-25T21:44:24.897+0000] {task_command.py:467} INFO - Running <TaskInstance: extract_weather.extract_data manual__2024-11-25T21:43:37.102564+00:00 [running]> on host 03f3e1ef676b
[2024-11-25T21:44:24.996+0000] {taskinstance.py:3131} INFO - Exporting env vars: AIRFLOW_CTX_DAG_OWNER='***' AIRFLOW_CTX_DAG_ID='extract_weather' AIRFLOW_CTX_TASK_ID='extract_data' AIRFLOW_CTX_EXECUTION_DATE='2024-11-25T21:43:37.102564+00:00' AIRFLOW_CTX_TRY_NUMBER='2' AIRFLOW_CTX_DAG_RUN_ID='manual__2024-11-25T21:43:37.102564+00:00'
[2024-11-25T21:44:24.997+0000] {taskinstance.py:731} INFO - ::endgroup::
[2024-11-25T21:44:25.014+0000] {operator.py:23} INFO - Fetching weather in Moscow
[2024-11-25T21:44:25.027+0000] {base.py:84} INFO - Retrieving connection 'weather_api'
[2024-11-25T21:44:25.667+0000] {operator.py:27} INFO - Fetched {'temp_c': -3.0, 'condition': 'Light snow'}
[2024-11-25T21:44:25.668+0000] {operator.py:29} INFO - Writing weather to /data/Moscow_20241126.json
[2024-11-25T21:44:25.675+0000] {taskinstance.py:3310} ERROR - Task failed with exception
Traceback (most recent call last):
  File "/home/airflow/.local/lib/python3.12/site-packages/airflow/models/taskinstance.py", line 767, in _execute_task
    result = _execute_callable(context=context, **execute_callable_kwargs)
             ^^^^^^^^^^^^^^^^^^^^^^^^^^^^^^^^^^^^^^^^^^^^^^^^^^^^^^^^^^^^^
  File "/home/airflow/.local/lib/python3.12/site-packages/airflow/models/taskinstance.py", line 733, in _execute_callable
    return ExecutionCallableRunner(
           ^^^^^^^^^^^^^^^^^^^^^^^^
  File "/home/airflow/.local/lib/python3.12/site-packages/airflow/utils/operator_helpers.py", line 252, in run
    return self.func(*args, **kwargs)
           ^^^^^^^^^^^^^^^^^^^^^^^^^^
  File "/home/airflow/.local/lib/python3.12/site-packages/airflow/models/baseoperator.py", line 406, in wrapper
    return func(self, *args, **kwargs)
           ^^^^^^^^^^^^^^^^^^^^^^^^^^^
  File "/opt/airflow/dags/custom/operator.py", line 32, in execute
    os.makedirs(file_path, exist_ok=True)
  File "<frozen os>", line 225, in makedirs
PermissionError: [Errno 13] Permission denied: '/data'
[2024-11-25T21:44:25.693+0000] {taskinstance.py:1225} INFO - Marking task as UP_FOR_RETRY. dag_id=extract_weather, task_id=extract_data, run_id=manual__2024-11-25T21:43:37.102564+00:00, execution_date=20241125T214337, start_date=20241125T214424, end_date=20241125T214425
[2024-11-25T21:44:25.710+0000] {taskinstance.py:340} INFO - ::group::Post task execution logs
[2024-11-25T21:44:25.710+0000] {standard_task_runner.py:124} ERROR - Failed to execute job 5 for task extract_data ([Errno 13] Permission denied: '/data'; 120)
Traceback (most recent call last):
  File "/home/airflow/.local/lib/python3.12/site-packages/airflow/task/task_runner/standard_task_runner.py", line 117, in _start_by_fork
    ret = args.func(args, dag=self.dag)
          ^^^^^^^^^^^^^^^^^^^^^^^^^^^^^
  File "/home/airflow/.local/lib/python3.12/site-packages/airflow/cli/cli_config.py", line 49, in command
    return func(*args, **kwargs)
           ^^^^^^^^^^^^^^^^^^^^^
  File "/home/airflow/.local/lib/python3.12/site-packages/airflow/utils/cli.py", line 115, in wrapper
    return f(*args, **kwargs)
           ^^^^^^^^^^^^^^^^^^
  File "/home/airflow/.local/lib/python3.12/site-packages/airflow/cli/commands/task_command.py", line 483, in task_run
    task_return_code = _run_task_by_selected_method(args, _dag, ti)
                       ^^^^^^^^^^^^^^^^^^^^^^^^^^^^^^^^^^^^^^^^^^^^
  File "/home/airflow/.local/lib/python3.12/site-packages/airflow/cli/commands/task_command.py", line 256, in _run_task_by_selected_method
    return _run_raw_task(args, ti)
           ^^^^^^^^^^^^^^^^^^^^^^^
  File "/home/airflow/.local/lib/python3.12/site-packages/airflow/cli/commands/task_command.py", line 341, in _run_raw_task
    return ti._run_raw_task(
           ^^^^^^^^^^^^^^^^^
  File "/home/airflow/.local/lib/python3.12/site-packages/airflow/utils/session.py", line 97, in wrapper
    return func(*args, session=session, **kwargs)
           ^^^^^^^^^^^^^^^^^^^^^^^^^^^^^^^^^^^^^^
  File "/home/airflow/.local/lib/python3.12/site-packages/airflow/models/taskinstance.py", line 3004, in _run_raw_task
    return _run_raw_task(
           ^^^^^^^^^^^^^^
  File "/home/airflow/.local/lib/python3.12/site-packages/airflow/models/taskinstance.py", line 273, in _run_raw_task
    TaskInstance._execute_task_with_callbacks(
  File "/home/airflow/.local/lib/python3.12/site-packages/airflow/models/taskinstance.py", line 3158, in _execute_task_with_callbacks
    result = self._execute_task(context, task_orig)
             ^^^^^^^^^^^^^^^^^^^^^^^^^^^^^^^^^^^^^^
  File "/home/airflow/.local/lib/python3.12/site-packages/airflow/models/taskinstance.py", line 3182, in _execute_task
    return _execute_task(self, context, task_orig)
           ^^^^^^^^^^^^^^^^^^^^^^^^^^^^^^^^^^^^^^^
  File "/home/airflow/.local/lib/python3.12/site-packages/airflow/models/taskinstance.py", line 767, in _execute_task
    result = _execute_callable(context=context, **execute_callable_kwargs)
             ^^^^^^^^^^^^^^^^^^^^^^^^^^^^^^^^^^^^^^^^^^^^^^^^^^^^^^^^^^^^^
  File "/home/airflow/.local/lib/python3.12/site-packages/airflow/models/taskinstance.py", line 733, in _execute_callable
    return ExecutionCallableRunner(
           ^^^^^^^^^^^^^^^^^^^^^^^^
  File "/home/airflow/.local/lib/python3.12/site-packages/airflow/utils/operator_helpers.py", line 252, in run
    return self.func(*args, **kwargs)
           ^^^^^^^^^^^^^^^^^^^^^^^^^^
  File "/home/airflow/.local/lib/python3.12/site-packages/airflow/models/baseoperator.py", line 406, in wrapper
    return func(self, *args, **kwargs)
           ^^^^^^^^^^^^^^^^^^^^^^^^^^^
  File "/opt/airflow/dags/custom/operator.py", line 32, in execute
    os.makedirs(file_path, exist_ok=True)
  File "<frozen os>", line 225, in makedirs
PermissionError: [Errno 13] Permission denied: '/data'
[2024-11-25T21:44:25.736+0000] {local_task_job_runner.py:266} INFO - Task exited with return code 1
[2024-11-25T21:44:25.756+0000] {taskinstance.py:3900} INFO - 0 downstream tasks scheduled from follow-on schedule check
[2024-11-25T21:44:25.758+0000] {local_task_job_runner.py:245} INFO - ::endgroup::
